<?xml version="1.0" ?>
<!-- =================================================================================== -->
<!-- |    This document was autogenerated by xacro from er7.urdf.xacro                 | -->
<!-- |    EDITING THIS FILE BY HAND IS NOT RECOMMENDED                                 | -->
<!-- =================================================================================== -->
<robot name="er7" xmlns:xacro="http://www.ros.org/wiki/xacro">
  <!-- Defining the colors used in this robot -->
  <material name="Black">
    <color rgba="0 0 0 1"/>
  </material>
  <material name="White">
    <color rgba="1 1 1 1"/>
  </material>
  <material name="Blue">
    <color rgba="0 0 1 1"/>
  </material>
  <material name="Red">
    <color rgba="1 0 0 1"/>
  </material>
  <!-- joint list -->
  <joint name="joint_1" type="revolute">
    <origin rpy="0 0 0" xyz="0 0 0"/>
    <axis xyz="0 0 1"/>
    <parent link="base_link"/>
    <child link="link_1"/>
    <limit effort="0" lower="-2.967" upper="2.967" velocity="6.632"/>
  </joint>
  <joint name="joint_2" type="revolute">
    <origin rpy="1.570795 0 0" xyz="0.05 0 0.3885"/>
    <axis xyz="0 0 1"/>
    <parent link="link_1"/>
    <child link="link_2"/>
    <limit effort="0" lower="-2.443" upper="1.152" velocity="6.109"/>
  </joint>
  <joint name="joint_3" type="revolute">
    <origin rpy="0 0 1.570795" xyz="0 0.33 0"/>
    <axis xyz="0 0 1"/>
    <parent link="link_2"/>
    <child link="link_3"/>
    <limit effort="0" lower="-1.222" upper="3.228" velocity="6.981"/>
  </joint>
  <joint name="joint_4" type="revolute">
    <origin rpy="1.570795 0 0" xyz="0.05 0 0"/>
    <axis xyz="0 0 1"/>
    <parent link="link_3"/>
    <child link="link_4"/>
    <limit effort="0" lower="-3.316" upper="3.316" velocity="7.854"/>
  </joint>
  <joint name="joint_5" type="revolute">
    <origin rpy="-1.570795 0 0" xyz="0 0 0.332"/>
    <axis xyz="0 0 1"/>
    <parent link="link_4"/>
    <child link="link_5"/>
    <limit effort="0" lower="-2.094" upper="2.094" velocity="7.854"/>
  </joint>
  <joint name="joint_6" type="revolute">
    <origin rpy="1.570795 0 0" xyz="0 -0.085 0"/>
    <axis xyz="0 0 1"/>
    <parent link="link_5"/>
    <child link="link_6"/>
    <limit effort="0" lower="-6.283" upper="6.283" velocity="13.963"/>
  </joint>
  <joint name="joint_6-tool0" type="fixed">
    <parent link="link_6"/>
    <child link="tool0"/>
    <origin rpy="0 0 0" xyz="0 0 0"/>
  </joint>
  <!-- ROS base_link to KeMotion World Coordinates transform -->
  <joint name="base_link-base" type="fixed">
    <origin rpy="0 0 0" xyz="0 0 0"/>
    <parent link="base_link"/>
    <child link="base"/>
  </joint>
  <!-- link list -->
  <link name="base"/>
  <link name="base_link"/>
  <link name="link_1">
    <visual>
      <origin rpy="0 0 0" xyz="0 0 0.19425"/>
      <geometry>
        <cylinder length="0.3885" radius="0.05"/>
      </geometry>
      <material name="Blue"/>
    </visual>
    <collision>
      <origin rpy="0 0 0" xyz="0 0 0.19425"/>
      <geometry>
        <cylinder length="0.3885" radius="0.05"/>
      </geometry>
    </collision>
    <inertial>
      <mass value="1"/>
      <inertia ixx="0.05093575" ixy="0" ixz="0" iyy="0.05093575" iyz="0" izz="0.00125"/>
    </inertial>
  </link>
  <link name="link_2">
    <visual>
      <origin rpy="-1.570795 0 0" xyz="0 0.165 0"/>
      <geometry>
        <cylinder length="0.33" radius="0.03"/>
      </geometry>
      <material name="White"/>
    </visual>
    <collision>
      <origin rpy="-1.570795 0 0" xyz="0 0.165 0"/>
      <geometry>
        <cylinder length="0.33" radius="0.03"/>
      </geometry>
    </collision>
    <inertial>
      <mass value="0.8"/>
      <inertia ixx="0.02922" ixy="0" ixz="0" iyy="0.00036" iyz="0" izz="0.02922"/>
    </inertial>
  </link>
  <link name="link_3">
    <visual>
      <origin rpy="0 1.570795 0" xyz="0.025 0 0"/>
      <geometry>
        <cylinder length="0.05" radius="0.03"/>
      </geometry>
      <material name="Blue"/>
    </visual>
    <collision>
      <origin rpy="0 1.570795 0" xyz="0.025 0 0"/>
      <geometry>
        <cylinder length="0.05" radius="0.03"/>
      </geometry>
    </collision>
    <inertial>
      <mass value="0.7"/>
      <inertia ixx="0.000315" ixy="0" ixz="0" iyy="0.000740833333333" iyz="0" izz="0.000740833333333"/>
    </inertial>
  </link>
  <link name="link_4">
    <visual>
      <origin rpy="0 0 0" xyz="0 0 0.166"/>
      <geometry>
        <cylinder length="0.332" radius="0.03"/>
      </geometry>
      <material name="Red"/>
    </visual>
    <collision>
      <origin rpy="0 0 0" xyz="0 0 0.166"/>
      <geometry>
        <cylinder length="0.332" radius="0.03"/>
      </geometry>
    </collision>
    <inertial>
      <mass value="0.7"/>
      <inertia ixx="0.0258764333333" ixy="0" ixz="0" iyy="0.0258764333333" iyz="0" izz="0.000315"/>
    </inertial>
  </link>
  <link name="link_5">
    <visual>
      <origin rpy="1.570795 0 0" xyz="0 -0.0425 0"/>
      <geometry>
        <cylinder length="0.085" radius="0.03"/>
      </geometry>
      <material name="Blue"/>
    </visual>
    <collision>
      <origin rpy="1.570795 0 0" xyz="0 -0.0425 0"/>
      <geometry>
        <cylinder length="0.085" radius="0.03"/>
      </geometry>
    </collision>
    <inertial>
      <mass value="0.6"/>
      <inertia ixx="0.00158" ixy="0" ixz="0" iyy="0.00027" iyz="0" izz="0.00158"/>
    </inertial>
  </link>
  <link name="link_6">
    <visual>
      <origin rpy="0 0 0" xyz="0 0 -0.005"/>
      <geometry>
        <cylinder length="0.01" radius="0.03"/>
      </geometry>
      <material name="White"/>
    </visual>
    <collision>
      <origin rpy="0 0 0" xyz="0 0 -0.005"/>
      <geometry>
        <cylinder length="0.01" radius="0.03"/>
      </geometry>
    </collision>
    <inertial>
      <mass value="0.3"/>
      <inertia ixx="7.75e-05" ixy="0" ixz="0" iyy="7.75e-05" iyz="0" izz="0.000135"/>
    </inertial>
  </link>
  <link name="tool0"/>
</robot>
