<?xml version="1.0" ?>
<!-- =================================================================================== -->
<!-- |    This document was autogenerated by xacro from er12.urdf.xacro                | -->
<!-- |    EDITING THIS FILE BY HAND IS NOT RECOMMENDED                                 | -->
<!-- =================================================================================== -->
<robot name="er12" xmlns:xacro="http://www.ros.org/wiki/xacro">
  <!-- Defining the colors used in this robot -->
  <material name="Black">
    <color rgba="0 0 0 1"/>
  </material>
  <material name="White">
    <color rgba="1 1 1 1"/>
  </material>
  <material name="Blue">
    <color rgba="0 0 1 1"/>
  </material>
  <material name="Red">
    <color rgba="1 0 0 1"/>
  </material>
  <!-- joint list -->
  <joint name="joint_1" type="revolute">
    <origin rpy="0 0 0" xyz="0 0 0"/>
    <axis xyz="0 0 1"/>
    <parent link="base_link"/>
    <child link="link_1"/>
    <limit effort="0" lower="-2.87979" upper="2.87979" velocity="6.9813"/>
  </joint>
  <joint name="joint_2" type="revolute">
    <origin rpy="1.570795 0 0" xyz="0.18653296 0 0.43"/>
    <axis xyz="0 0 1"/>
    <parent link="link_1"/>
    <child link="link_2"/>
    <limit effort="0" lower="-1.4835" upper="2.87979" velocity="6.9813"/>
  </joint>
  <joint name="joint_3" type="revolute">
    <origin rpy="0 0 1.570795" xyz="0 0.6702776 0"/>
    <axis xyz="0 0 1"/>
    <parent link="link_2"/>
    <child link="link_3"/>
    <limit effort="0" lower="-2.5307" upper="1.309" velocity="4.7123889"/>
  </joint>
  <joint name="joint_4" type="revolute">
    <origin rpy="1.570795 0 0" xyz="0.1093699 0 0"/>
    <axis xyz="0 0 1"/>
    <parent link="link_3"/>
    <child link="link_4"/>
    <limit effort="0" lower="-6.2832" upper="6.2832" velocity="4.712"/>
  </joint>
  <joint name="joint_5" type="revolute">
    <origin rpy="-1.570795 0 0" xyz="0 0 0.70014177"/>
    <axis xyz="0 0 1"/>
    <parent link="link_4"/>
    <child link="link_5"/>
    <limit effort="0" lower="-2.269" upper="2.269" velocity="12.217"/>
  </joint>
  <joint name="joint_6" type="revolute">
    <origin rpy="1.570795 0 0" xyz="0 -0.12 0"/>
    <axis xyz="0 0 1"/>
    <parent link="link_5"/>
    <child link="link_6"/>
    <limit effort="0" lower="-6.2832" upper="6.2832" velocity="13.614"/>
  </joint>
  <joint name="joint_6-tool0" type="fixed">
    <parent link="link_6"/>
    <child link="tool0"/>
    <origin rpy="0 0 0" xyz="0 0 0"/>
  </joint>
  <!-- ROS base_link to KeMotion World Coordinates transform -->
  <joint name="base_link-base" type="fixed">
    <origin rpy="0 0 0" xyz="0 0 0"/>
    <parent link="base_link"/>
    <child link="base"/>
  </joint>
  <!-- link list -->
  <link name="base"/>
  <link name="base_link"/>
  <link name="link_1">
    <visual>
      <origin rpy="0 0 0" xyz="0 0 0.215"/>
      <geometry>
        <cylinder length="0.43" radius="0.19"/>
      </geometry>
      <material name="Blue"/>
    </visual>
    <collision>
      <origin rpy="0 0 0" xyz="0 0 0.215"/>
      <geometry>
        <cylinder length="0.43" radius="0.19"/>
      </geometry>
    </collision>
    <inertial>
      <mass value="1"/>
      <inertia ixx="0.0706583333333" ixy="0" ixz="0" iyy="0.0706583333333" iyz="0" izz="0.01805"/>
    </inertial>
  </link>
  <link name="link_2">
    <visual>
      <origin rpy="-1.570795 0 0" xyz="0 0.3351388 0"/>
      <geometry>
        <cylinder length="0.6702776" radius="0.03"/>
      </geometry>
      <material name="White"/>
    </visual>
    <collision>
      <origin rpy="-1.570795 0 0" xyz="0 0.3351388 0"/>
      <geometry>
        <cylinder length="0.6702776" radius="0.03"/>
      </geometry>
    </collision>
    <inertial>
      <mass value="0.8"/>
      <inertia ixx="0.11998588295" ixy="0" ixz="0" iyy="0.00036" iyz="0" izz="0.11998588295"/>
    </inertial>
  </link>
  <link name="link_3">
    <visual>
      <origin rpy="0 1.570795 0" xyz="0.05468495 0 0"/>
      <geometry>
        <cylinder length="0.1093699" radius="0.03"/>
      </geometry>
      <material name="Blue"/>
    </visual>
    <collision>
      <origin rpy="0 1.570795 0" xyz="0.05468495 0 0"/>
      <geometry>
        <cylinder length="0.1093699" radius="0.03"/>
      </geometry>
    </collision>
    <inertial>
      <mass value="0.7"/>
      <inertia ixx="0.000315" ixy="0" ixz="0" iyy="0.0029485808394" iyz="0" izz="0.0029485808394"/>
    </inertial>
  </link>
  <link name="link_4">
    <visual>
      <origin rpy="0 0 0" xyz="0 0 0.350070885"/>
      <geometry>
        <cylinder length="0.70014177" radius="0.03"/>
      </geometry>
      <material name="Red"/>
    </visual>
    <collision>
      <origin rpy="0 0 0" xyz="0 0 0.350070885"/>
      <geometry>
        <cylinder length="0.70014177" radius="0.03"/>
      </geometry>
    </collision>
    <inertial>
      <mass value="0.7"/>
      <inertia ixx="0.114537149556" ixy="0" ixz="0" iyy="0.114537149556" iyz="0" izz="0.000315"/>
    </inertial>
  </link>
  <link name="link_5">
    <visual>
      <origin rpy="1.570795 0 0" xyz="0 -0.06 0"/>
      <geometry>
        <cylinder length="0.12" radius="0.03"/>
      </geometry>
      <material name="Blue"/>
    </visual>
    <collision>
      <origin rpy="1.570795 0 0" xyz="0 -0.06 0"/>
      <geometry>
        <cylinder length="0.12" radius="0.03"/>
      </geometry>
    </collision>
    <inertial>
      <mass value="0.6"/>
      <inertia ixx="0.003015" ixy="0" ixz="0" iyy="0.00027" iyz="0" izz="0.003015"/>
    </inertial>
  </link>
  <link name="link_6">
    <visual>
      <origin rpy="0 0 0" xyz="0 0 -0.005"/>
      <geometry>
        <cylinder length="0.01" radius="0.03"/>
      </geometry>
      <material name="White"/>
    </visual>
    <collision>
      <origin rpy="0 0 0" xyz="0 0 -0.005"/>
      <geometry>
        <cylinder length="0.01" radius="0.03"/>
      </geometry>
    </collision>
    <inertial>
      <mass value="0.3"/>
      <inertia ixx="7.75e-05" ixy="0" ixz="0" iyy="7.75e-05" iyz="0" izz="0.000135"/>
    </inertial>
  </link>
  <link name="tool0"/>
</robot>

